======================================================================
FAIL: tempest.api.object_storage.test_account_bulk.BulkTest.test_bulk_delete[gate]
tags: worker-0
----------------------------------------------------------------------
Empty attachments:
  pythonlogging:''
  stderr
  stdout

Traceback (most recent call last):
  File "/work/tempest/tempest/test.py", line 154, in wrapper
    return func(*func_args, **func_kwargs)
  File "/work/tempest/tempest/api/object_storage/test_account_bulk.py", line 109, in test_bulk_delete
    self._upload_archive(filepath)
  File "/work/tempest/tempest/api/object_storage/test_account_bulk.py", line 59, in _upload_archive
    params=params)
  File "/work/tempest/tempest/services/object_storage/account_client.py", line 46, in create_account
    resp, body = self.put(url, data, headers)
  File "/home/adam/.local/lib/python2.7/site-packages/tempest_lib/common/rest_client.py", line 315, in put
    return self.request('PUT', url, extra_headers, headers, body)
  File "/work/tempest/tempest/common/service_client.py", line 61, in request
    headers=headers, body=body)
  File "/home/adam/.local/lib/python2.7/site-packages/tempest_lib/common/rest_client.py", line 629, in request
    resp, resp_body)
  File "/home/adam/.local/lib/python2.7/site-packages/tempest_lib/common/rest_client.py", line 737, in _error_checker
    raise exceptions.UnexpectedResponseCode(str(resp.status))
tempest_lib.exceptions.UnexpectedResponseCode: Unexpected response code received
Details: 405
======================================================================
FAIL: tempest.api.object_storage.test_account_bulk.BulkTest.test_bulk_delete_by_POST[gate]
tags: worker-0
----------------------------------------------------------------------
Empty attachments:
  pythonlogging:''
  stderr
  stdout

Traceback (most recent call last):
  File "/work/tempest/tempest/test.py", line 154, in wrapper
    return func(*func_args, **func_kwargs)
  File "/work/tempest/tempest/api/object_storage/test_account_bulk.py", line 136, in test_bulk_delete_by_POST
    self._upload_archive(filepath)
  File "/work/tempest/tempest/api/object_storage/test_account_bulk.py", line 59, in _upload_archive
    params=params)
  File "/work/tempest/tempest/services/object_storage/account_client.py", line 46, in create_account
    resp, body = self.put(url, data, headers)
  File "/home/adam/.local/lib/python2.7/site-packages/tempest_lib/common/rest_client.py", line 315, in put
    return self.request('PUT', url, extra_headers, headers, body)
  File "/work/tempest/tempest/common/service_client.py", line 61, in request
    headers=headers, body=body)
  File "/home/adam/.local/lib/python2.7/site-packages/tempest_lib/common/rest_client.py", line 629, in request
    resp, resp_body)
  File "/home/adam/.local/lib/python2.7/site-packages/tempest_lib/common/rest_client.py", line 737, in _error_checker
    raise exceptions.UnexpectedResponseCode(str(resp.status))
tempest_lib.exceptions.UnexpectedResponseCode: Unexpected response code received
Details: 405
======================================================================
FAIL: tempest.api.object_storage.test_account_bulk.BulkTest.test_extract_archive[gate]
tags: worker-0
----------------------------------------------------------------------
Empty attachments:
  pythonlogging:''
  stderr
  stdout

Traceback (most recent call last):
  File "/work/tempest/tempest/test.py", line 154, in wrapper
    return func(*func_args, **func_kwargs)
  File "/work/tempest/tempest/api/object_storage/test_account_bulk.py", line 73, in test_extract_archive
    resp, _ = self._upload_archive(filepath)
  File "/work/tempest/tempest/api/object_storage/test_account_bulk.py", line 59, in _upload_archive
    params=params)
  File "/work/tempest/tempest/services/object_storage/account_client.py", line 46, in create_account
    resp, body = self.put(url, data, headers)
  File "/home/adam/.local/lib/python2.7/site-packages/tempest_lib/common/rest_client.py", line 315, in put
    return self.request('PUT', url, extra_headers, headers, body)
  File "/work/tempest/tempest/common/service_client.py", line 61, in request
    headers=headers, body=body)
  File "/home/adam/.local/lib/python2.7/site-packages/tempest_lib/common/rest_client.py", line 629, in request
    resp, resp_body)
  File "/home/adam/.local/lib/python2.7/site-packages/tempest_lib/common/rest_client.py", line 737, in _error_checker
    raise exceptions.UnexpectedResponseCode(str(resp.status))
tempest_lib.exceptions.UnexpectedResponseCode: Unexpected response code received
Details: 405
======================================================================
FAIL: tempest.api.object_storage.test_account_quotas_negative.AccountQuotasNegativeTest.test_user_modify_quota[gate,negative,smoke]
tags: worker-0
----------------------------------------------------------------------
Empty attachments:
  pythonlogging:''
  stderr
  stdout

Traceback (most recent call last):
  File "/work/tempest/tempest/test.py", line 154, in wrapper
    return func(*func_args, **func_kwargs)
  File "/work/tempest/tempest/api/object_storage/test_account_quotas_negative.py", line 90, in test_user_modify_quota
    {"Quota-Bytes": ""})
  File "/home/adam/.local/lib/python2.7/site-packages/testtools/testcase.py", line 422, in assertRaises
    self.assertThat(our_callable, matcher)
  File "/home/adam/.local/lib/python2.7/site-packages/testtools/testcase.py", line 435, in assertThat
    raise mismatch_error
testtools.matchers._impl.MismatchError: <bound method AccountClient.create_account_metadata of <tempest.services.object_storage.account_client.AccountClient object at 0x7fcbac579990>> returned ({'date': 'Sat, 23 Apr 2016 13:24:27 GMT', 'status': '204', 'connection': 'close', 'content-type': 'text/plain; charset=utf-8', 'x-trans-id': 'tx00000000000000000005a-00571b778b-100c-default'}, '')
======================================================================
FAIL: tempest.api.object_storage.test_account_services.AccountTest.test_list_extensions[gate,smoke]
tags: worker-0
----------------------------------------------------------------------
Empty attachments:
  pythonlogging:''
  stderr
  stdout

Traceback (most recent call last):
  File "/work/tempest/tempest/api/object_storage/test_account_services.py", line 120, in test_list_extensions
    resp, extensions = self.account_client.list_extensions()
  File "/work/tempest/tempest/services/object_storage/account_client.py", line 154, in list_extensions
    resp, body = self.get('info')
  File "/home/adam/.local/lib/python2.7/site-packages/tempest_lib/common/rest_client.py", line 267, in get
    return self.request('GET', url, extra_headers, headers)
  File "/work/tempest/tempest/common/service_client.py", line 65, in request
    raise exceptions.NotFound(ex)
tempest.exceptions.NotFound: Object not found
Details: Object not found
Details: {"Code":"NoSuchBucket","BucketName":"info","RequestId":"tx000000000000000000080-00571b778c-100c-default","HostId":"100c-default-default"}
======================================================================
FAIL: tempest.api.object_storage.test_container_quotas.ContainerQuotasTest.test_upload_large_object[gate,smoke]
tags: worker-0
----------------------------------------------------------------------
Empty attachments:
  pythonlogging:''
  stderr
  stdout

Traceback (most recent call last):
  File "/work/tempest/tempest/test.py", line 154, in wrapper
    return func(*func_args, **func_kwargs)
  File "/work/tempest/tempest/api/object_storage/test_container_quotas.py", line 80, in test_upload_large_object
    self.container_name, object_name, data)
  File "/home/adam/.local/lib/python2.7/site-packages/testtools/testcase.py", line 422, in assertRaises
    self.assertThat(our_callable, matcher)
  File "/home/adam/.local/lib/python2.7/site-packages/testtools/testcase.py", line 435, in assertThat
    raise mismatch_error
testtools.matchers._impl.MismatchError: <bound method ObjectClient.create_object of <tempest.services.object_storage.object_client.ObjectClient object at 0x7fcbac1e8590>> returned ({'status': '201', 'content-length': '0', 'last-modified': 'Sat, 23 Apr 2016 13:24:33 GMT', 'connection': 'close', 'etag': '8ca276f3eb3b33e9a2d0c11eb7f82137', 'x-trans-id': 'tx0000000000000000000e1-00571b7791-100c-default', 'date': 'Sat, 23 Apr 2016 13:24:33 GMT', 'content-type': 'application/json; charset=utf-8'}, '')
======================================================================
FAIL: tempest.api.object_storage.test_container_quotas.ContainerQuotasTest.test_upload_too_many_objects[gate,smoke]
tags: worker-0
----------------------------------------------------------------------
Empty attachments:
  pythonlogging:''
  stderr
  stdout

Traceback (most recent call last):
  File "/work/tempest/tempest/test.py", line 154, in wrapper
    return func(*func_args, **func_kwargs)
  File "/work/tempest/tempest/api/object_storage/test_container_quotas.py", line 98, in test_upload_too_many_objects
    self.container_name, "OverQuotaObject", "")
  File "/home/adam/.local/lib/python2.7/site-packages/testtools/testcase.py", line 422, in assertRaises
    self.assertThat(our_callable, matcher)
  File "/home/adam/.local/lib/python2.7/site-packages/testtools/testcase.py", line 435, in assertThat
    raise mismatch_error
testtools.matchers._impl.MismatchError: <bound method ObjectClient.create_object of <tempest.services.object_storage.object_client.ObjectClient object at 0x7fcbac1e8590>> returned ({'status': '201', 'content-length': '0', 'last-modified': 'Sat, 23 Apr 2016 13:24:34 GMT', 'connection': 'close', 'etag': 'd41d8cd98f00b204e9800998ecf8427e', 'x-trans-id': 'tx0000000000000000000eb-00571b7792-100c-default', 'date': 'Sat, 23 Apr 2016 13:24:34 GMT', 'content-type': 'application/json; charset=utf-8'}, '')
======================================================================
FAIL: tempest.api.object_storage.test_container_staticweb.StaticWebTest.test_web_index
tags: worker-0
----------------------------------------------------------------------
Empty attachments:
  pythonlogging:''
  stderr
  stdout

Traceback (most recent call last):
  File "/work/tempest/tempest/test.py", line 154, in wrapper
    return func(*func_args, **func_kwargs)
  File "/work/tempest/tempest/api/object_storage/test_container_staticweb.py", line 73, in test_web_index
    self.assertHeaders(resp, 'Object', 'GET')
  File "/work/tempest/tempest/api/object_storage/base.py", line 108, in assertHeaders
    target, method))
  File "/home/adam/.local/lib/python2.7/site-packages/testtools/testcase.py", line 435, in assertThat
    raise mismatch_error
testtools.matchers._impl.MismatchError: etag header does not exist
======================================================================
FAIL: tempest.api.object_storage.test_container_staticweb.StaticWebTest.test_web_listing_css
tags: worker-0
----------------------------------------------------------------------
Empty attachments:
  pythonlogging:''
  stderr
  stdout

Traceback (most recent call last):
  File "/work/tempest/tempest/test.py", line 154, in wrapper
    return func(*func_args, **func_kwargs)
  File "/work/tempest/tempest/api/object_storage/test_container_staticweb.py", line 138, in test_web_listing_css
    self.assertIn(css, body)
  File "/home/adam/.local/lib/python2.7/site-packages/testtools/testcase.py", line 356, in assertIn
    self.assertThat(haystack, Contains(needle), message)
  File "/home/adam/.local/lib/python2.7/site-packages/testtools/testcase.py", line 435, in assertThat
    raise mismatch_error
testtools.matchers._impl.MismatchError: '<link rel="stylesheet" type="text/css" href="listings.css" />' not in '404TestObject-432466139\nTestObject-432466139'
======================================================================
FAIL: tempest.api.object_storage.test_container_sync_middleware.ContainerSyncMiddlewareTest.test_container_synchronization[slow]
tags: worker-0
----------------------------------------------------------------------
Empty attachments:
  pythonlogging:''
  stderr
  stdout

Traceback (most recent call last):
  File "/work/tempest/tempest/test.py", line 154, in wrapper
    return func(*func_args, **func_kwargs)
  File "/work/tempest/tempest/api/object_storage/test_container_sync_middleware.py", line 51, in test_container_synchronization
    self._test_container_synchronization(make_headers)
  File "/work/tempest/tempest/api/object_storage/test_container_sync.py", line 106, in _test_container_synchronization
    'Different object lists in containers.')
  File "/home/adam/.local/lib/python2.7/site-packages/testtools/testcase.py", line 350, in assertEqual
    self.assertThat(observed, matcher, message)
  File "/home/adam/.local/lib/python2.7/site-packages/testtools/testcase.py", line 435, in assertThat
    raise mismatch_error
testtools.matchers._impl.MismatchError: !=:
reference = {u'TestSyncObject-2033215629': {u'bytes': 25,
                                u'content_type': u'application/json',
                                u'hash': u'274610b29440db5deba772e673c9465f',
                                u'last_modified': u'2016-04-23T13:24:41.408Z',
                                u'name': u'TestSyncObject-2033215629'}}
actual    = {}
: Different object lists in containers.
======================================================================
FAIL: tempest.api.object_storage.test_crossdomain.CrossdomainTest.test_get_crossdomain_policy
tags: worker-0
----------------------------------------------------------------------
Empty attachments:
  pythonlogging:''
  stderr
  stdout

Traceback (most recent call last):
  File "/work/tempest/tempest/test.py", line 154, in wrapper
    return func(*func_args, **func_kwargs)
  File "/work/tempest/tempest/api/object_storage/test_crossdomain.py", line 44, in test_get_crossdomain_policy
    resp, body = self.account_client.get("crossdomain.xml", {})
  File "/home/adam/.local/lib/python2.7/site-packages/tempest_lib/common/rest_client.py", line 267, in get
    return self.request('GET', url, extra_headers, headers)
  File "/work/tempest/tempest/common/service_client.py", line 61, in request
    headers=headers, body=body)
  File "/home/adam/.local/lib/python2.7/site-packages/tempest_lib/common/rest_client.py", line 629, in request
    resp, resp_body)
  File "/home/adam/.local/lib/python2.7/site-packages/tempest_lib/common/rest_client.py", line 666, in _error_checker
    raise exceptions.InvalidContentType(str(resp.status))
tempest_lib.exceptions.InvalidContentType: Invalid content type provided
Details: 404
======================================================================
FAIL: tempest.api.object_storage.test_healthcheck.HealthcheckTest.test_get_healthcheck
tags: worker-0
----------------------------------------------------------------------
Empty attachments:
  pythonlogging:''
  stderr
  stdout

Traceback (most recent call last):
  File "/work/tempest/tempest/api/object_storage/test_healthcheck.py", line 37, in test_get_healthcheck
    resp, _ = self.account_client.get("healthcheck", {})
  File "/home/adam/.local/lib/python2.7/site-packages/tempest_lib/common/rest_client.py", line 267, in get
    return self.request('GET', url, extra_headers, headers)
  File "/work/tempest/tempest/common/service_client.py", line 61, in request
    headers=headers, body=body)
  File "/home/adam/.local/lib/python2.7/site-packages/tempest_lib/common/rest_client.py", line 629, in request
    resp, resp_body)
  File "/home/adam/.local/lib/python2.7/site-packages/tempest_lib/common/rest_client.py", line 666, in _error_checker
    raise exceptions.InvalidContentType(str(resp.status))
tempest_lib.exceptions.InvalidContentType: Invalid content type provided
Details: 404
======================================================================
FAIL: tempest.api.object_storage.test_object_formpost.ObjectFormPostTest.test_post_object_using_form[gate]
tags: worker-0
----------------------------------------------------------------------
Empty attachments:
  pythonlogging:''
  stderr
  stdout

Traceback (most recent call last):
  File "/work/tempest/tempest/test.py", line 154, in wrapper
    return func(*func_args, **func_kwargs)
  File "/work/tempest/tempest/api/object_storage/test_object_formpost.py", line 119, in test_post_object_using_form
    resp, body = self.object_client.post(url, body, headers=headers)
  File "/home/adam/.local/lib/python2.7/site-packages/tempest_lib/common/rest_client.py", line 252, in post
    return self.request('POST', url, extra_headers, headers, body)
  File "/work/tempest/tempest/common/service_client.py", line 65, in request
    raise exceptions.NotFound(ex)
tempest.exceptions.NotFound: Object not found
Details: Object not found
Details: NoSuchKey
======================================================================
FAIL: tempest.api.object_storage.test_object_formpost_negative.ObjectFormPostNegativeTest.test_post_object_using_form_expired[gate,negative]
tags: worker-0
----------------------------------------------------------------------
Empty attachments:
  pythonlogging:''
  stderr
  stdout

Traceback (most recent call last):
  File "/work/tempest/tempest/test.py", line 154, in wrapper
    return func(*func_args, **func_kwargs)
  File "/work/tempest/tempest/api/object_storage/test_object_formpost_negative.py", line 122, in test_post_object_using_form_expired
    url, body, headers=headers)
  File "/home/adam/.local/lib/python2.7/site-packages/testtools/testcase.py", line 422, in assertRaises
    self.assertThat(our_callable, matcher)
  File "/home/adam/.local/lib/python2.7/site-packages/testtools/testcase.py", line 433, in assertThat
    mismatch_error = self._matchHelper(matchee, matcher, message, verbose)
  File "/home/adam/.local/lib/python2.7/site-packages/testtools/testcase.py", line 483, in _matchHelper
    mismatch = matcher.match(matchee)
  File "/home/adam/.local/lib/python2.7/site-packages/testtools/matchers/_exception.py", line 108, in match
    mismatch = self.exception_matcher.match(exc_info)
  File "/home/adam/.local/lib/python2.7/site-packages/testtools/matchers/_higherorder.py", line 62, in match
    mismatch = matcher.match(matchee)
  File "/home/adam/.local/lib/python2.7/site-packages/testtools/testcase.py", line 414, in match
    reraise(*matchee)
  File "/home/adam/.local/lib/python2.7/site-packages/testtools/matchers/_exception.py", line 101, in match
    result = matchee()
  File "/home/adam/.local/lib/python2.7/site-packages/testtools/testcase.py", line 969, in __call__
    return self._callable_object(*self._args, **self._kwargs)
  File "/home/adam/.local/lib/python2.7/site-packages/tempest_lib/common/rest_client.py", line 252, in post
    return self.request('POST', url, extra_headers, headers, body)
  File "/work/tempest/tempest/common/service_client.py", line 65, in request
    raise exceptions.NotFound(ex)
tempest.exceptions.NotFound: Object not found
Details: Object not found
Details: NoSuchKey
======================================================================
FAIL: tempest.api.object_storage.test_object_formpost_negative.ObjectFormPostNegativeTest.test_post_object_using_form_invalid_signature[gate]
tags: worker-0
----------------------------------------------------------------------
Empty attachments:
  pythonlogging:''
  stderr
  stdout

Traceback (most recent call last):
  File "/work/tempest/tempest/test.py", line 154, in wrapper
    return func(*func_args, **func_kwargs)
  File "/work/tempest/tempest/api/object_storage/test_object_formpost_negative.py", line 138, in test_post_object_using_form_invalid_signature
    url, body, headers=headers)
  File "/home/adam/.local/lib/python2.7/site-packages/testtools/testcase.py", line 422, in assertRaises
    self.assertThat(our_callable, matcher)
  File "/home/adam/.local/lib/python2.7/site-packages/testtools/testcase.py", line 433, in assertThat
    mismatch_error = self._matchHelper(matchee, matcher, message, verbose)
  File "/home/adam/.local/lib/python2.7/site-packages/testtools/testcase.py", line 483, in _matchHelper
    mismatch = matcher.match(matchee)
  File "/home/adam/.local/lib/python2.7/site-packages/testtools/matchers/_exception.py", line 108, in match
    mismatch = self.exception_matcher.match(exc_info)
  File "/home/adam/.local/lib/python2.7/site-packages/testtools/matchers/_higherorder.py", line 62, in match
    mismatch = matcher.match(matchee)
  File "/home/adam/.local/lib/python2.7/site-packages/testtools/testcase.py", line 414, in match
    reraise(*matchee)
  File "/home/adam/.local/lib/python2.7/site-packages/testtools/matchers/_exception.py", line 101, in match
    result = matchee()
  File "/home/adam/.local/lib/python2.7/site-packages/testtools/testcase.py", line 969, in __call__
    return self._callable_object(*self._args, **self._kwargs)
  File "/home/adam/.local/lib/python2.7/site-packages/tempest_lib/common/rest_client.py", line 252, in post
    return self.request('POST', url, extra_headers, headers, body)
  File "/work/tempest/tempest/common/service_client.py", line 65, in request
    raise exceptions.NotFound(ex)
tempest.exceptions.NotFound: Object not found
Details: Object not found
Details: NoSuchKey
======================================================================
FAIL: tempest.api.object_storage.test_object_slo.ObjectSloTest.test_delete_large_object[gate]
tags: worker-0
----------------------------------------------------------------------
Empty attachments:
  pythonlogging:''
  stderr
  stdout

Traceback (most recent call last):
  File "/work/tempest/tempest/api/object_storage/test_object_slo.py", line 165, in test_delete_large_object
    self.assertIn('transfer-encoding', resp)
  File "/home/adam/.local/lib/python2.7/site-packages/testtools/testcase.py", line 356, in assertIn
    self.assertThat(haystack, Contains(needle), message)
  File "/home/adam/.local/lib/python2.7/site-packages/testtools/testcase.py", line 435, in assertThat
    raise mismatch_error
testtools.matchers._impl.MismatchError: 'transfer-encoding' not in {'status': '200', 'content-length': '87', 'connection': 'close', 'x-trans-id': 'tx0000000000000000002d4-00571b77c9-100c-default', 'date': 'Sat, 23 Apr 2016 13:25:29 GMT', 'content-type': 'text/plain; charset=utf-8'}
======================================================================
FAIL: tempest.api.object_storage.test_object_version.ContainerTest.test_versioned_container[gate,smoke]
tags: worker-0
----------------------------------------------------------------------
Empty attachments:
  pythonlogging:''
  stderr
  stdout

Traceback (most recent call last):
  File "/work/tempest/tempest/api/object_storage/test_object_version.py", line 69, in test_versioned_container
    vers_container_name)
  File "/work/tempest/tempest/api/object_storage/test_object_version.py", line 45, in assertContainer
    self.assertEqual(header_value, versioned)
  File "/home/adam/.local/lib/python2.7/site-packages/testtools/testcase.py", line 350, in assertEqual
    self.assertThat(observed, matcher, message)
  File "/home/adam/.local/lib/python2.7/site-packages/testtools/testcase.py", line 435, in assertThat
    raise mismatch_error
testtools.matchers._impl.MismatchError: 'Missing Header' != 'TestVersionContainer-955555843'
======================================================================
FAIL: process-returncode
tags: worker-0
----------------------------------------------------------------------
Binary content:
  traceback (test/plain; charset=""utf8"")
Ran 18 tests in 69.689s
FAILED (id=347, failures=18)
