======================================================================
FAIL: tempest.api.object_storage.test_account_bulk.BulkTest.test_bulk_delete[gate]
tags: worker-0
----------------------------------------------------------------------
Empty attachments:
  pythonlogging:''
  stderr
  stdout

Traceback (most recent call last):
  File "/work/tempest/tempest/test.py", line 154, in wrapper
    return func(*func_args, **func_kwargs)
  File "/work/tempest/tempest/api/object_storage/test_account_bulk.py", line 109, in test_bulk_delete
    self._upload_archive(filepath)
  File "/work/tempest/tempest/api/object_storage/test_account_bulk.py", line 59, in _upload_archive
    params=params)
  File "/work/tempest/tempest/services/object_storage/account_client.py", line 46, in create_account
    resp, body = self.put(url, data, headers)
  File "/home/adam/.local/lib/python2.7/site-packages/tempest_lib/common/rest_client.py", line 315, in put
    return self.request('PUT', url, extra_headers, headers, body)
  File "/work/tempest/tempest/common/service_client.py", line 61, in request
    headers=headers, body=body)
  File "/home/adam/.local/lib/python2.7/site-packages/tempest_lib/common/rest_client.py", line 629, in request
    resp, resp_body)
  File "/home/adam/.local/lib/python2.7/site-packages/tempest_lib/common/rest_client.py", line 737, in _error_checker
    raise exceptions.UnexpectedResponseCode(str(resp.status))
tempest_lib.exceptions.UnexpectedResponseCode: Unexpected response code received
Details: 405
======================================================================
FAIL: tempest.api.object_storage.test_account_bulk.BulkTest.test_bulk_delete_by_POST[gate]
tags: worker-0
----------------------------------------------------------------------
Empty attachments:
  pythonlogging:''
  stderr
  stdout

Traceback (most recent call last):
  File "/work/tempest/tempest/test.py", line 154, in wrapper
    return func(*func_args, **func_kwargs)
  File "/work/tempest/tempest/api/object_storage/test_account_bulk.py", line 136, in test_bulk_delete_by_POST
    self._upload_archive(filepath)
  File "/work/tempest/tempest/api/object_storage/test_account_bulk.py", line 59, in _upload_archive
    params=params)
  File "/work/tempest/tempest/services/object_storage/account_client.py", line 46, in create_account
    resp, body = self.put(url, data, headers)
  File "/home/adam/.local/lib/python2.7/site-packages/tempest_lib/common/rest_client.py", line 315, in put
    return self.request('PUT', url, extra_headers, headers, body)
  File "/work/tempest/tempest/common/service_client.py", line 61, in request
    headers=headers, body=body)
  File "/home/adam/.local/lib/python2.7/site-packages/tempest_lib/common/rest_client.py", line 629, in request
    resp, resp_body)
  File "/home/adam/.local/lib/python2.7/site-packages/tempest_lib/common/rest_client.py", line 737, in _error_checker
    raise exceptions.UnexpectedResponseCode(str(resp.status))
tempest_lib.exceptions.UnexpectedResponseCode: Unexpected response code received
Details: 405
======================================================================
FAIL: tempest.api.object_storage.test_account_bulk.BulkTest.test_extract_archive[gate]
tags: worker-0
----------------------------------------------------------------------
Empty attachments:
  pythonlogging:''
  stderr
  stdout

Traceback (most recent call last):
  File "/work/tempest/tempest/test.py", line 154, in wrapper
    return func(*func_args, **func_kwargs)
  File "/work/tempest/tempest/api/object_storage/test_account_bulk.py", line 73, in test_extract_archive
    resp, _ = self._upload_archive(filepath)
  File "/work/tempest/tempest/api/object_storage/test_account_bulk.py", line 59, in _upload_archive
    params=params)
  File "/work/tempest/tempest/services/object_storage/account_client.py", line 46, in create_account
    resp, body = self.put(url, data, headers)
  File "/home/adam/.local/lib/python2.7/site-packages/tempest_lib/common/rest_client.py", line 315, in put
    return self.request('PUT', url, extra_headers, headers, body)
  File "/work/tempest/tempest/common/service_client.py", line 61, in request
    headers=headers, body=body)
  File "/home/adam/.local/lib/python2.7/site-packages/tempest_lib/common/rest_client.py", line 629, in request
    resp, resp_body)
  File "/home/adam/.local/lib/python2.7/site-packages/tempest_lib/common/rest_client.py", line 737, in _error_checker
    raise exceptions.UnexpectedResponseCode(str(resp.status))
tempest_lib.exceptions.UnexpectedResponseCode: Unexpected response code received
Details: 405
======================================================================
FAIL: tempest.api.object_storage.test_account_quotas_negative.AccountQuotasNegativeTest.test_user_modify_quota[gate,negative,smoke]
tags: worker-0
----------------------------------------------------------------------
Empty attachments:
  pythonlogging:''
  stderr
  stdout

Traceback (most recent call last):
  File "/work/tempest/tempest/test.py", line 154, in wrapper
    return func(*func_args, **func_kwargs)
  File "/work/tempest/tempest/api/object_storage/test_account_quotas_negative.py", line 90, in test_user_modify_quota
    {"Quota-Bytes": ""})
  File "/home/adam/.local/lib/python2.7/site-packages/testtools/testcase.py", line 422, in assertRaises
    self.assertThat(our_callable, matcher)
  File "/home/adam/.local/lib/python2.7/site-packages/testtools/testcase.py", line 435, in assertThat
    raise mismatch_error
testtools.matchers._impl.MismatchError: <bound method AccountClient.create_account_metadata of <tempest.services.object_storage.account_client.AccountClient object at 0x7f3c9f5739d0>> returned ({'date': 'Thu, 21 Apr 2016 12:00:50 GMT', 'status': '204', 'connection': 'close', 'content-type': 'text/plain; charset=utf-8', 'x-trans-id': 'tx000000000000000000014-005718c0f2-1012-default'}, '')
======================================================================
FAIL: tempest.api.object_storage.test_account_services.AccountTest.test_list_extensions[gate,smoke]
tags: worker-0
----------------------------------------------------------------------
Empty attachments:
  pythonlogging:''
  stderr
  stdout

Traceback (most recent call last):
  File "/work/tempest/tempest/api/object_storage/test_account_services.py", line 120, in test_list_extensions
    resp, extensions = self.account_client.list_extensions()
  File "/work/tempest/tempest/services/object_storage/account_client.py", line 154, in list_extensions
    resp, body = self.get('info')
  File "/home/adam/.local/lib/python2.7/site-packages/tempest_lib/common/rest_client.py", line 267, in get
    return self.request('GET', url, extra_headers, headers)
  File "/work/tempest/tempest/common/service_client.py", line 65, in request
    raise exceptions.NotFound(ex)
tempest.exceptions.NotFound: Object not found
Details: Object not found
Details: {"Code":"NoSuchBucket","BucketName":"info","RequestId":"tx00000000000000000003b-005718c0f4-1012-default","HostId":"1012-default-default"}
======================================================================
FAIL: tempest.api.object_storage.test_account_services_negative.AccountNegativeTest.test_list_containers_with_non_authorized_user[gate,negative]
tags: worker-0
----------------------------------------------------------------------
Empty attachments:
  pythonlogging:''
  stderr
  stdout

Traceback (most recent call last):
  File "/work/tempest/tempest/api/object_storage/test_account_services_negative.py", line 49, in test_list_containers_with_non_authorized_user
    params=params)
  File "/home/adam/.local/lib/python2.7/site-packages/testtools/testcase.py", line 422, in assertRaises
    self.assertThat(our_callable, matcher)
  File "/home/adam/.local/lib/python2.7/site-packages/testtools/testcase.py", line 435, in assertThat
    raise mismatch_error
testtools.matchers._impl.MismatchError: <bound method AccountClient.list_account_containers of <tempest.services.object_storage.account_client.AccountClient object at 0x7f3c9f41de10>> returned ({'status': '200', 'content-length': '2', 'content-location': 'http://127.0.0.1:8000/swift/v1/?format=json', 'x-account-object-count': '0', 'connection': 'close', 'x-timestamp': '1461240055.16555', 'x-account-bytes-used-actual': '0', 'x-trans-id': 'tx000000000000000000059-005718c0f7-1012-default', 'date': 'Thu, 21 Apr 2016 12:00:55 GMT', 'x-account-bytes-used': '0', 'x-account-container-count': '0', 'content-type': 'application/json; charset=utf-8', 'accept-ranges': 'bytes'}, [])
======================================================================
FAIL: tempest.api.object_storage.test_container_acl.ObjectTestACLs.test_read_object_with_rights[gate,smoke]
tags: worker-0
----------------------------------------------------------------------
Empty attachments:
  pythonlogging:''
  stderr
  stdout

Traceback (most recent call last):
  File "/work/tempest/tempest/api/object_storage/test_container_acl.py", line 60, in test_read_object_with_rights
    self.container_name, object_name)
  File "/work/tempest/tempest/services/object_storage/object_client.py", line 89, in get_object
    resp, body = self.get(url, headers=headers)
  File "/home/adam/.local/lib/python2.7/site-packages/tempest_lib/common/rest_client.py", line 267, in get
    return self.request('GET', url, extra_headers, headers)
  File "/work/tempest/tempest/common/service_client.py", line 63, in request
    raise exceptions.Unauthorized(ex)
tempest.exceptions.Unauthorized: Unauthorized
Details: Unauthorized
Details: AccessDenied
======================================================================
FAIL: tempest.api.object_storage.test_container_acl.ObjectTestACLs.test_write_object_with_rights[gate,smoke]
tags: worker-0
----------------------------------------------------------------------
Empty attachments:
  pythonlogging:''
  stderr
  stdout

Traceback (most recent call last):
  File "/work/tempest/tempest/api/object_storage/test_container_acl.py", line 81, in test_write_object_with_rights
    object_name, 'data', headers={})
  File "/work/tempest/tempest/services/object_storage/object_client.py", line 40, in create_object
    resp, body = self.put(url, data, headers)
  File "/home/adam/.local/lib/python2.7/site-packages/tempest_lib/common/rest_client.py", line 315, in put
    return self.request('PUT', url, extra_headers, headers, body)
  File "/work/tempest/tempest/common/service_client.py", line 63, in request
    raise exceptions.Unauthorized(ex)
tempest.exceptions.Unauthorized: Unauthorized
Details: Unauthorized
Details: AccessDenied
======================================================================
FAIL: tempest.api.object_storage.test_container_quotas.ContainerQuotasTest.test_upload_large_object[gate,smoke]
tags: worker-0
----------------------------------------------------------------------
Empty attachments:
  pythonlogging:''
  stderr
  stdout

Traceback (most recent call last):
  File "/work/tempest/tempest/test.py", line 154, in wrapper
    return func(*func_args, **func_kwargs)
  File "/work/tempest/tempest/api/object_storage/test_container_quotas.py", line 80, in test_upload_large_object
    self.container_name, object_name, data)
  File "/home/adam/.local/lib/python2.7/site-packages/testtools/testcase.py", line 422, in assertRaises
    self.assertThat(our_callable, matcher)
  File "/home/adam/.local/lib/python2.7/site-packages/testtools/testcase.py", line 435, in assertThat
    raise mismatch_error
testtools.matchers._impl.MismatchError: <bound method ObjectClient.create_object of <tempest.services.object_storage.object_client.ObjectClient object at 0x7f3c9f1fd450>> returned ({'status': '201', 'content-length': '0', 'last-modified': 'Thu, 21 Apr 2016 12:00:59 GMT', 'connection': 'close', 'etag': '8ca276f3eb3b33e9a2d0c11eb7f82137', 'x-trans-id': 'tx00000000000000000009b-005718c0fb-1012-default', 'date': 'Thu, 21 Apr 2016 12:00:59 GMT', 'content-type': 'application/json; charset=utf-8'}, '')
======================================================================
FAIL: tempest.api.object_storage.test_container_quotas.ContainerQuotasTest.test_upload_too_many_objects[gate,smoke]
tags: worker-0
----------------------------------------------------------------------
Empty attachments:
  pythonlogging:''
  stderr
  stdout

Traceback (most recent call last):
  File "/work/tempest/tempest/test.py", line 154, in wrapper
    return func(*func_args, **func_kwargs)
  File "/work/tempest/tempest/api/object_storage/test_container_quotas.py", line 98, in test_upload_too_many_objects
    self.container_name, "OverQuotaObject", "")
  File "/home/adam/.local/lib/python2.7/site-packages/testtools/testcase.py", line 422, in assertRaises
    self.assertThat(our_callable, matcher)
  File "/home/adam/.local/lib/python2.7/site-packages/testtools/testcase.py", line 435, in assertThat
    raise mismatch_error
testtools.matchers._impl.MismatchError: <bound method ObjectClient.create_object of <tempest.services.object_storage.object_client.ObjectClient object at 0x7f3c9f1fd450>> returned ({'status': '201', 'content-length': '0', 'last-modified': 'Thu, 21 Apr 2016 12:01:00 GMT', 'connection': 'close', 'etag': 'd41d8cd98f00b204e9800998ecf8427e', 'x-trans-id': 'tx0000000000000000000a5-005718c0fc-1012-default', 'date': 'Thu, 21 Apr 2016 12:01:00 GMT', 'content-type': 'application/json; charset=utf-8'}, '')
======================================================================
FAIL: tempest.api.object_storage.test_container_staticweb.StaticWebTest.test_web_error
tags: worker-0
----------------------------------------------------------------------
Empty attachments:
  pythonlogging:''
  stderr
  stdout

Traceback (most recent call last):
  File "/work/tempest/tempest/test.py", line 154, in wrapper
    return func(*func_args, **func_kwargs)
  File "/work/tempest/tempest/api/object_storage/test_container_staticweb.py", line 165, in test_web_error
    self.container_name, "notexisting")
  File "/home/adam/.local/lib/python2.7/site-packages/testtools/testcase.py", line 422, in assertRaises
    self.assertThat(our_callable, matcher)
  File "/home/adam/.local/lib/python2.7/site-packages/testtools/testcase.py", line 433, in assertThat
    mismatch_error = self._matchHelper(matchee, matcher, message, verbose)
  File "/home/adam/.local/lib/python2.7/site-packages/testtools/testcase.py", line 483, in _matchHelper
    mismatch = matcher.match(matchee)
  File "/home/adam/.local/lib/python2.7/site-packages/testtools/matchers/_exception.py", line 108, in match
    mismatch = self.exception_matcher.match(exc_info)
  File "/home/adam/.local/lib/python2.7/site-packages/testtools/matchers/_higherorder.py", line 62, in match
    mismatch = matcher.match(matchee)
  File "/home/adam/.local/lib/python2.7/site-packages/testtools/testcase.py", line 414, in match
    reraise(*matchee)
  File "/home/adam/.local/lib/python2.7/site-packages/testtools/matchers/_exception.py", line 101, in match
    result = matchee()
  File "/home/adam/.local/lib/python2.7/site-packages/testtools/testcase.py", line 969, in __call__
    return self._callable_object(*self._args, **self._kwargs)
  File "/work/tempest/tempest/services/object_storage/object_client.py", line 89, in get_object
    resp, body = self.get(url, headers=headers)
  File "/home/adam/.local/lib/python2.7/site-packages/tempest_lib/common/rest_client.py", line 267, in get
    return self.request('GET', url, extra_headers, headers)
  File "/work/tempest/tempest/common/service_client.py", line 63, in request
    raise exceptions.Unauthorized(ex)
tempest.exceptions.Unauthorized: Unauthorized
Details: Unauthorized
Details: AccessDenied
======================================================================
FAIL: tempest.api.object_storage.test_container_staticweb.StaticWebTest.test_web_index
tags: worker-0
----------------------------------------------------------------------
Empty attachments:
  pythonlogging:''
  stderr
  stdout

Traceback (most recent call last):
  File "/work/tempest/tempest/test.py", line 154, in wrapper
    return func(*func_args, **func_kwargs)
  File "/work/tempest/tempest/api/object_storage/test_container_staticweb.py", line 71, in test_web_index
    headers={})
  File "/work/tempest/tempest/common/service_client.py", line 63, in request
    raise exceptions.Unauthorized(ex)
tempest.exceptions.Unauthorized: Unauthorized
Details: Unauthorized
Details: AccessDenied
======================================================================
FAIL: tempest.api.object_storage.test_container_staticweb.StaticWebTest.test_web_listing_css
tags: worker-0
----------------------------------------------------------------------
Empty attachments:
  pythonlogging:''
  stderr
  stdout

Traceback (most recent call last):
  File "/work/tempest/tempest/test.py", line 154, in wrapper
    return func(*func_args, **func_kwargs)
  File "/work/tempest/tempest/api/object_storage/test_container_staticweb.py", line 135, in test_web_listing_css
    headers={})
  File "/work/tempest/tempest/common/service_client.py", line 63, in request
    raise exceptions.Unauthorized(ex)
tempest.exceptions.Unauthorized: Unauthorized
Details: Unauthorized
Details: AccessDenied
======================================================================
FAIL: tempest.api.object_storage.test_container_sync_middleware.ContainerSyncMiddlewareTest.test_container_synchronization[slow]
tags: worker-0
----------------------------------------------------------------------
Empty attachments:
  pythonlogging:''
  stderr
  stdout

Traceback (most recent call last):
  File "/work/tempest/tempest/test.py", line 154, in wrapper
    return func(*func_args, **func_kwargs)
  File "/work/tempest/tempest/api/object_storage/test_container_sync_middleware.py", line 51, in test_container_synchronization
    self._test_container_synchronization(make_headers)
  File "/work/tempest/tempest/api/object_storage/test_container_sync.py", line 106, in _test_container_synchronization
    'Different object lists in containers.')
  File "/home/adam/.local/lib/python2.7/site-packages/testtools/testcase.py", line 350, in assertEqual
    self.assertThat(observed, matcher, message)
  File "/home/adam/.local/lib/python2.7/site-packages/testtools/testcase.py", line 435, in assertThat
    raise mismatch_error
testtools.matchers._impl.MismatchError: !=:
reference = {u'TestSyncObject-252014163': {u'bytes': 24,
                               u'content_type': u'application/json',
                               u'hash': u'1bd526967930db3222d297c285a50143',
                               u'last_modified': u'2016-04-21T12:01:09.753Z',
                               u'name': u'TestSyncObject-252014163'}}
actual    = {}
: Different object lists in containers.
======================================================================
FAIL: tempest.api.object_storage.test_crossdomain.CrossdomainTest.test_get_crossdomain_policy
tags: worker-0
----------------------------------------------------------------------
Empty attachments:
  pythonlogging:''
  stderr
  stdout

Traceback (most recent call last):
  File "/work/tempest/tempest/test.py", line 154, in wrapper
    return func(*func_args, **func_kwargs)
  File "/work/tempest/tempest/api/object_storage/test_crossdomain.py", line 44, in test_get_crossdomain_policy
    resp, body = self.account_client.get("crossdomain.xml", {})
  File "/home/adam/.local/lib/python2.7/site-packages/tempest_lib/common/rest_client.py", line 267, in get
    return self.request('GET', url, extra_headers, headers)
  File "/work/tempest/tempest/common/service_client.py", line 61, in request
    headers=headers, body=body)
  File "/home/adam/.local/lib/python2.7/site-packages/tempest_lib/common/rest_client.py", line 629, in request
    resp, resp_body)
  File "/home/adam/.local/lib/python2.7/site-packages/tempest_lib/common/rest_client.py", line 666, in _error_checker
    raise exceptions.InvalidContentType(str(resp.status))
tempest_lib.exceptions.InvalidContentType: Invalid content type provided
Details: 404
======================================================================
FAIL: tempest.api.object_storage.test_healthcheck.HealthcheckTest.test_get_healthcheck
tags: worker-0
----------------------------------------------------------------------
Empty attachments:
  pythonlogging:''
  stderr
  stdout

Traceback (most recent call last):
  File "/work/tempest/tempest/api/object_storage/test_healthcheck.py", line 37, in test_get_healthcheck
    resp, _ = self.account_client.get("healthcheck", {})
  File "/home/adam/.local/lib/python2.7/site-packages/tempest_lib/common/rest_client.py", line 267, in get
    return self.request('GET', url, extra_headers, headers)
  File "/work/tempest/tempest/common/service_client.py", line 61, in request
    headers=headers, body=body)
  File "/home/adam/.local/lib/python2.7/site-packages/tempest_lib/common/rest_client.py", line 629, in request
    resp, resp_body)
  File "/home/adam/.local/lib/python2.7/site-packages/tempest_lib/common/rest_client.py", line 666, in _error_checker
    raise exceptions.InvalidContentType(str(resp.status))
tempest_lib.exceptions.InvalidContentType: Invalid content type provided
Details: 404
======================================================================
FAIL: tempest.api.object_storage.test_object_formpost.ObjectFormPostTest.test_post_object_using_form[gate]
tags: worker-0
----------------------------------------------------------------------
Empty attachments:
  pythonlogging:''
  stderr
  stdout

Traceback (most recent call last):
  File "/work/tempest/tempest/test.py", line 154, in wrapper
    return func(*func_args, **func_kwargs)
  File "/work/tempest/tempest/api/object_storage/test_object_formpost.py", line 119, in test_post_object_using_form
    resp, body = self.object_client.post(url, body, headers=headers)
  File "/home/adam/.local/lib/python2.7/site-packages/tempest_lib/common/rest_client.py", line 252, in post
    return self.request('POST', url, extra_headers, headers, body)
  File "/work/tempest/tempest/common/service_client.py", line 65, in request
    raise exceptions.NotFound(ex)
tempest.exceptions.NotFound: Object not found
Details: Object not found
Details: NoSuchKey
======================================================================
FAIL: tempest.api.object_storage.test_object_formpost_negative.ObjectFormPostNegativeTest.test_post_object_using_form_expired[gate,negative]
tags: worker-0
----------------------------------------------------------------------
Empty attachments:
  pythonlogging:''
  stderr
  stdout

Traceback (most recent call last):
  File "/work/tempest/tempest/test.py", line 154, in wrapper
    return func(*func_args, **func_kwargs)
  File "/work/tempest/tempest/api/object_storage/test_object_formpost_negative.py", line 122, in test_post_object_using_form_expired
    url, body, headers=headers)
  File "/home/adam/.local/lib/python2.7/site-packages/testtools/testcase.py", line 422, in assertRaises
    self.assertThat(our_callable, matcher)
  File "/home/adam/.local/lib/python2.7/site-packages/testtools/testcase.py", line 433, in assertThat
    mismatch_error = self._matchHelper(matchee, matcher, message, verbose)
  File "/home/adam/.local/lib/python2.7/site-packages/testtools/testcase.py", line 483, in _matchHelper
    mismatch = matcher.match(matchee)
  File "/home/adam/.local/lib/python2.7/site-packages/testtools/matchers/_exception.py", line 108, in match
    mismatch = self.exception_matcher.match(exc_info)
  File "/home/adam/.local/lib/python2.7/site-packages/testtools/matchers/_higherorder.py", line 62, in match
    mismatch = matcher.match(matchee)
  File "/home/adam/.local/lib/python2.7/site-packages/testtools/testcase.py", line 414, in match
    reraise(*matchee)
  File "/home/adam/.local/lib/python2.7/site-packages/testtools/matchers/_exception.py", line 101, in match
    result = matchee()
  File "/home/adam/.local/lib/python2.7/site-packages/testtools/testcase.py", line 969, in __call__
    return self._callable_object(*self._args, **self._kwargs)
  File "/home/adam/.local/lib/python2.7/site-packages/tempest_lib/common/rest_client.py", line 252, in post
    return self.request('POST', url, extra_headers, headers, body)
  File "/work/tempest/tempest/common/service_client.py", line 65, in request
    raise exceptions.NotFound(ex)
tempest.exceptions.NotFound: Object not found
Details: Object not found
Details: NoSuchKey
======================================================================
FAIL: tempest.api.object_storage.test_object_formpost_negative.ObjectFormPostNegativeTest.test_post_object_using_form_invalid_signature[gate]
tags: worker-0
----------------------------------------------------------------------
Empty attachments:
  pythonlogging:''
  stderr
  stdout

Traceback (most recent call last):
  File "/work/tempest/tempest/test.py", line 154, in wrapper
    return func(*func_args, **func_kwargs)
  File "/work/tempest/tempest/api/object_storage/test_object_formpost_negative.py", line 138, in test_post_object_using_form_invalid_signature
    url, body, headers=headers)
  File "/home/adam/.local/lib/python2.7/site-packages/testtools/testcase.py", line 422, in assertRaises
    self.assertThat(our_callable, matcher)
  File "/home/adam/.local/lib/python2.7/site-packages/testtools/testcase.py", line 433, in assertThat
    mismatch_error = self._matchHelper(matchee, matcher, message, verbose)
  File "/home/adam/.local/lib/python2.7/site-packages/testtools/testcase.py", line 483, in _matchHelper
    mismatch = matcher.match(matchee)
  File "/home/adam/.local/lib/python2.7/site-packages/testtools/matchers/_exception.py", line 108, in match
    mismatch = self.exception_matcher.match(exc_info)
  File "/home/adam/.local/lib/python2.7/site-packages/testtools/matchers/_higherorder.py", line 62, in match
    mismatch = matcher.match(matchee)
  File "/home/adam/.local/lib/python2.7/site-packages/testtools/testcase.py", line 414, in match
    reraise(*matchee)
  File "/home/adam/.local/lib/python2.7/site-packages/testtools/matchers/_exception.py", line 101, in match
    result = matchee()
  File "/home/adam/.local/lib/python2.7/site-packages/testtools/testcase.py", line 969, in __call__
    return self._callable_object(*self._args, **self._kwargs)
  File "/home/adam/.local/lib/python2.7/site-packages/tempest_lib/common/rest_client.py", line 252, in post
    return self.request('POST', url, extra_headers, headers, body)
  File "/work/tempest/tempest/common/service_client.py", line 65, in request
    raise exceptions.NotFound(ex)
tempest.exceptions.NotFound: Object not found
Details: Object not found
Details: NoSuchKey
======================================================================
FAIL: tempest.api.object_storage.test_object_services.PublicObjectTest.test_access_public_container_object_without_using_creds[gate,smoke]
tags: worker-0
----------------------------------------------------------------------
Empty attachments:
  pythonlogging:''
  stderr
  stdout

Traceback (most recent call last):
  File "/work/tempest/tempest/api/object_storage/test_object_services.py", line 1013, in test_access_public_container_object_without_using_creds
    self.assertIn('x-container-read', resp_meta)
  File "/home/adam/.local/lib/python2.7/site-packages/testtools/testcase.py", line 356, in assertIn
    self.assertThat(haystack, Contains(needle), message)
  File "/home/adam/.local/lib/python2.7/site-packages/testtools/testcase.py", line 435, in assertThat
    raise mismatch_error
testtools.matchers._impl.MismatchError: 'x-container-read' not in {'status': '204', 'content-length': '0', 'x-container-object-count': '1', 'accept-ranges': 'bytes', 'x-storage-policy': 'default-placement', 'x-container-bytes-used-actual': '4096', 'x-container-bytes-used': '17', 'connection': 'close', 'x-timestamp': '0.00000', 'x-trans-id': 'tx00000000000000000027d-005718c137-1012-default', 'date': 'Thu, 21 Apr 2016 12:01:59 GMT', 'content-type': 'application/json; charset=utf-8'}
======================================================================
FAIL: tempest.api.object_storage.test_object_services.PublicObjectTest.test_access_public_object_with_another_user_creds[gate,smoke]
tags: worker-0
----------------------------------------------------------------------
Empty attachments:
  pythonlogging:''
  stderr
  stdout

Traceback (most recent call last):
  File "/work/tempest/tempest/api/object_storage/test_object_services.py", line 1050, in test_access_public_object_with_another_user_creds
    self.assertIn('x-container-read', resp)
  File "/home/adam/.local/lib/python2.7/site-packages/testtools/testcase.py", line 356, in assertIn
    self.assertThat(haystack, Contains(needle), message)
  File "/home/adam/.local/lib/python2.7/site-packages/testtools/testcase.py", line 435, in assertThat
    raise mismatch_error
testtools.matchers._impl.MismatchError: 'x-container-read' not in {'status': '204', 'content-length': '0', 'x-container-object-count': '1', 'accept-ranges': 'bytes', 'x-storage-policy': 'default-placement', 'x-container-bytes-used-actual': '4096', 'x-container-bytes-used': '16', 'connection': 'close', 'x-timestamp': '0.00000', 'x-trans-id': 'tx000000000000000000284-005718c138-1012-default', 'date': 'Thu, 21 Apr 2016 12:02:00 GMT', 'content-type': 'application/json; charset=utf-8'}
======================================================================
FAIL: tempest.api.object_storage.test_object_slo.ObjectSloTest.test_delete_large_object[gate]
tags: worker-0
----------------------------------------------------------------------
Empty attachments:
  pythonlogging:''
  stderr
  stdout

Traceback (most recent call last):
  File "/work/tempest/tempest/api/object_storage/test_object_slo.py", line 165, in test_delete_large_object
    self.assertIn('transfer-encoding', resp)
  File "/home/adam/.local/lib/python2.7/site-packages/testtools/testcase.py", line 356, in assertIn
    self.assertThat(haystack, Contains(needle), message)
  File "/home/adam/.local/lib/python2.7/site-packages/testtools/testcase.py", line 435, in assertThat
    raise mismatch_error
testtools.matchers._impl.MismatchError: 'transfer-encoding' not in {'status': '200', 'content-length': '87', 'connection': 'close', 'x-trans-id': 'tx00000000000000000028c-005718c138-1012-default', 'date': 'Thu, 21 Apr 2016 12:02:00 GMT', 'content-type': 'text/plain; charset=utf-8'}
======================================================================
FAIL: tempest.api.object_storage.test_object_version.ContainerTest.test_versioned_container[gate,smoke]
tags: worker-0
----------------------------------------------------------------------
Empty attachments:
  pythonlogging:''
  stderr
  stdout

Traceback (most recent call last):
  File "/work/tempest/tempest/api/object_storage/test_object_version.py", line 69, in test_versioned_container
    vers_container_name)
  File "/work/tempest/tempest/api/object_storage/test_object_version.py", line 45, in assertContainer
    self.assertEqual(header_value, versioned)
  File "/home/adam/.local/lib/python2.7/site-packages/testtools/testcase.py", line 350, in assertEqual
    self.assertThat(observed, matcher, message)
  File "/home/adam/.local/lib/python2.7/site-packages/testtools/testcase.py", line 435, in assertThat
    raise mismatch_error
testtools.matchers._impl.MismatchError: 'Missing Header' != 'TestVersionContainer-1619115371'
======================================================================
FAIL: process-returncode
tags: worker-0
----------------------------------------------------------------------
Binary content:
  traceback (test/plain; charset=""utf8"")
Ran 24 tests in 86.672s
FAILED (id=339, failures=24)
